Workbook

Sheet Annotation data (organs)
A1: Specie | B1: Exp. num. | C1: Bar code | D1: Tray | E1: Date time | F1: Full-Part-Organs | G1: Full-Part-Plants | H1: File name | I1: Obj ID 1 | J1: Obj ID 2 | K1: Obj ID 3 | L1: Obj ID 4 | M1: Obj ID 5 | N1: Obj ID 6 | O1: Obj ID 7 | P1: Obj ID 8 | Q1: Obj ID 9 | R1: Obj ID 10 | S1: Obj ID 11 | T1: Obj ID 12 | U1: Obj ID 13
A2: species | B2: studyId | C2: obsUnitId | E2: collectionDate | H2: sampleId | I2: variableId | J2: variableId | K2: variableId | L2: variableId | M2: variableId | N2: variableId | O2: variableId | P2: variableId | Q2: variableId | R2: variableId | S2: variableId | T2: variableId | U2: variableId
A3: mungbean | B3: 50 | C3: 27 | D3: 0_0 | E3: 20220524T041419 | F3: Full | G3: Full | H3: 50-27-0_0-20220524T041419 | I3: 1
A4: mungbean | B4: 50 | C4: 27 | D4: 0_0 | E4: 20220524T041419 | F4: Full | G4: Full | H4: 50-27-0_0-20220524T041419 | I4: 2
A5: mungbean | B5: 50 | C5: 27 | D5: 0_0 | E5: 20220524T041419 | F5: Full | G5: Full | H5: 50-27-0_0-20220524T041419 | I5: 3
A6: mungbean | B6: 50 | C6: 27 | D6: 0_0 | E6: 20220524T041419 | F6: Full | G6: Full | H6: 50-27-0_0-20220524T041419 | I6: 4
A7: mungbean | B7: 50 | C7: 27 | D7: 0_0 | E7: 20220524T041419 | F7: Full | G7: Full | H7: 50-27-0_0-20220524T041419 | I7: 5
A8: mungbean | B8: 50 | C8: 27 | D8: 0_0 | E8: 20220524T041419 | F8: Full | G8: Full | H8: 50-27-0_0-20220524T041419 | I8: 6
A9: mungbean | B9: 50 | C9: 27 | D9: 0_0 | E9: 20220524T041419 | F9: Full | G9: Full | H9: 50-27-0_0-20220524T041419 | I9: 7
A10: mungbean | B10: 50 | C10: 27 | D10: 0_0 | E10: 20220524T041419 | F10: Full | G10: Full | H10: 50-27-0_0-20220524T041419 | I10: 8
A11: mungbean | B11: 50 | C11: 27 | D11: 0_0 | E11: 20220524T041419 | F11: Full | G11: Full | H11: 50-27-0_0-20220524T041419 | I11: 9
A12: mungbean | B12: 50 | C12: 27 | D12: 0_0 | E12: 20220524T041419 | F12: Full | G12: Full | H12: 50-27-0_0-20220524T041419 | I12: 10
A13: mungbean | B13: 50 | C13: 27 | D13: 0_0 | E13: 20220524T041419 | F13: Full | G13: Full | H13: 50-27-0_0-20220524T041419 | I13: 11
A14: mungbean | B14: 50 | C14: 27 | D14: 0_0 | E14: 20220524T041419 | F14: Full | G14: Full | H14: 50-27-0_0-20220524T041419 | I14: 12
... A32: mungbean | B32: 50 | C32: 27 | D32: 0_0 | E32: 20220527T045102 | F32: Full | G32: Full | H32: 50-27-0_0-20220527T045102 | I32: 1
A33: mungbean | B33: 50 | C33: 27 | D33: 0_0 | E33: 20220527T045102 | F33: Full | G33: Full | H33: 50-27-0_0-20220527T045102 | I33: 2 | J33: 17
A34: mungbean | B34: 50 | C34: 27 | D34: 0_0 | E34: 20220527T045102 | F34: Full | G34: Full | H34: 50-27-0_0-20220527T045102 | I34: 3 | J34: 18
A35: mungbean | B35: 50 | C35: 27 | D35: 0_0 | E35: 20220527T045102 | F35: Full | G35: Full | H35: 50-27-0_0-20220527T045102 | I35: 4
A36: mungbean | B36: 50 | C36: 27 | D36: 0_0 | E36: 20220527T045102 | F36: Full | G36: Full | H36: 50-27-0_0-20220527T045102 | I36: 5 | J36: 19
A37: mungbean | B37: 50 | C37: 27 | D37: 0_0 | E37: 20220527T045102 | F37: Full | G37: Full | H37: 50-27-0_0-20220527T045102 | I37: 6 | J37: 20
A38: mungbean | B38: 50 | C38: 27 | D38: 0_0 | E38: 20220527T045102 | F38: Full | G38: Full | H38: 50-27-0_0-20220527T045102 | I38: 7
A39: mungbean | B39: 50 | C39: 27 | D39: 0_0 | E39: 20220527T045102 | F39: Full | G39: Full | H39: 50-27-0_0-20220527T045102 | I39: 8
A40: mungbean | B40: 50 | C40: 27 | D40: 0_0 | E40: 20220527T045102 | F40: Full | G40: Full | H40: 50-27-0_0-20220527T045102 | I40: 9
A41: mungbean | B41: 50 | C41: 27 | D41: 0_0 | E41: 20220527T045102 | F41: Full | G41: Full | H41: 50-27-0_0-20220527T045102 | I41: 10
A42: mungbean | B42: 50 | C42: 27 | D42: 0_0 | E42: 20220527T045102 | F42: Full | G42: Full | H42: 50-27-0_0-20220527T045102 | I42: 11
A43: mungbean | B43: 50 | C43: 27 | D43: 0_0 | E43: 20220527T045102 | F43: Full | G43: Full | H43: 50-27-0_0-20220527T045102 | I43: 12
A44: mungbean | B44: 50 | C44: 27 | D44: 0_0 | E44: 20220527T045102 | F44: Full | G44: Full | H44: 50-27-0_0-20220527T045102 | I44: 13
A45: mungbean | B45: 50 | C45: 27 | D45: 0_0 | E45: 20220527T045102 | F45: Full | G45: Full | H45: 50-27-0_0-20220527T045102 | I45: 14
A46: mungbean | B46: 50 | C46: 27 | D46: 0_0 | E46: 20220527T045102 | F46: Full | G46: Full | H46: 50-27-0_0-20220527T045102 | I46: 15
A47: mungbean | B47: 50 | C47: 27 | D47: 0_0 | E47: 20220527T045102 | F47: Full | G47: Full | H47: 50-27-0_0-20220527T045102 | I47: 16
A48: mungbean | B48: 50 | C48: 27 | D48: 0_0 | E48: 20220527T045102 | F48: Full | G48: Full | H48: 50-27-0_0-20220527T045102 | I48: 21
A49: mungbean | B49: 50 | C49: 27 | D49: 0_0 | E49: 20220527T045102 | F49: Full | G49: Full | H49: 50-27-0_0-20220527T045102 | I49: 22
A50: mungbean | B50: 50 | C50: 27 | D50: 0_0 | E50: 20220530T074538 | F50: Full | G50: Full | H50: 50-27-0_0-20220530T074538 | I50: 1 | J50: 3 | K50: 5
A51: mungbean | B51: 50 | C51: 27 | D51: 0_0 | E51: 20220530T074538 | F51: Full | G51: Full | H51: 50-27-0_0-20220530T074538 | I51: 2 | J51: 4 | K51: 6
A52: mungbean | B52: 50 | C52: 27 | D52: 0_0 | E52: 20220531T042054 | F52: Full | G52: Full | H52: 50-27-0_0-20220531T042054 | I52: 1 | J52: 3 | K52: 6 | L52: 8 | M52: 9
A53: mungbean | B53: 50 | C53: 27 | D53: 0_0 | E53: 20220531T042054 | F53: Full | G53: Full | H53: 50-27-0_0-20220531T042054 | I53: 2 | J53: 4 | K53: 5 | L53: 7 | M53: 10
A54: mungbean | B54: 50 | C54: 27 | D54: 0_0 | E54: 20220601T033109 | F54: Full | G54: Full | H54: 50-27-0_0-20220601T033109 | I54: 1 | J54: 2 | K54: 4 | L54: 7 | M54: 9
A55: mungbean | B55: 50 | C55: 27 | D55: 0_0 | E55: 20220601T033109 | F55: Full | G55: Full | H55: 50-27-0_0-20220601T033109 | I55: 3 | J55: 5 | K55: 6 | L55: 8
A56: mungbean | B56: 50 | C56: 27 | D56: 0_0 | E56: 20220602T052138 | F56: Full | G56: Full | H56: 50-27-0_0-20220602T052138 | I56: 1 | J56: 2 | K56: 5 | L56: 9 | M56: 10
A57: mungbean | B57: 50 | C57: 27 | D57: 0_0 | E57: 20220602T052138 | F57: Full | G57: Full | H57: 50-27-0_0-20220602T052138 | I57: 3 | J57: 4 | K57: 6 | L57: 7 | M57: 8
...

Sheet Annotated microplots
A1: Specie | B1: Exp. num. | C1: Bar code | D1: Tray | E1: Date time | F1: Full-Part-Organs | G1: Full-Part-Plants | H1: File name
A2: species | B2: studyId | C2: obsUnitId | E2: collectionDate | H2: sampleId
A3: mungbean | B3: 50 | C3: 27 | D3: 0_0 | E3: 20220524T041419 | F3: Full | G3: Full | H3: 50-27-0_0-20220524T041419
A4: mungbean | B4: 50 | C4: 27 | D4: 0_0 | E4: 20220525T030449 | F4: Full | G4: Full | H4: 50-27-0_0-20220525T030449
A5: mungbean | B5: 50 | C5: 27 | D5: 0_0 | E5: 20220527T045102 | F5: Full | G5: Full | H5: 50-27-0_0-20220527T045102
A6: mungbean | B6: 50 | C6: 27 | D6: 0_0 | E6: 20220530T074538 | F6: Full | G6: Full | H6: 50-27-0_0-20220530T074538
A7: mungbean | B7: 50 | C7: 27 | D7: 0_0 | E7: 20220531T042054 | F7: Full | G7: Full | H7: 50-27-0_0-20220531T042054
A8: mungbean | B8: 50 | C8: 27 | D8: 0_0 | E8: 20220601T033109 | F8: Full | G8: Full | H8: 50-27-0_0-20220601T033109
A9: mungbean | B9: 50 | C9: 27 | D9: 0_0 | E9: 20220602T052138 | F9: Full | G9: Full | H9: 50-27-0_0-20220602T052138
A10: mungbean | B10: 50 | C10: 27 | D10: 0_1 | E10: 20220523T042520 | F10: Full | G10: Full | H10: 50-27-0_1-20220523T042520
A11: mungbean | B11: 50 | C11: 27 | D11: 0_1 | E11: 20220524T041419 | F11: Full | G11: Full | H11: 50-27-0_1-20220524T041419
A12: mungbean | B12: 50 | C12: 27 | D12: 0_1 | E12: 20220525T030449 | F12: Full | G12: Full | H12: 50-27-0_1-20220525T030449
A13: mungbean | B13: 50 | C13: 27 | D13: 0_1 | E13: 20220527T045102 | F13: Full | G13: Full | H13: 50-27-0_1-20220527T045102
A14: mungbean | B14: 50 | C14: 27 | D14: 0_1 | E14: 20220530T074538 | F14: Full | G14: Full | H14: 50-27-0_1-20220530T074538
... A229: mungbean | B229: 59 | C229: 79 | D229: 1_8 | E229: 20230729T054442 | F229: Full | G229: Full | H229: 59-79-1_8-20230729T054442
A1656: mungbean
A1657: cowpea
A1658: common bean
A1659: lima bean

Sheet STUDY
A1: Study unique ID | B1: Study title | C1: Study description | D1: Start date of study | E1: End date of study | F1: Contact institution | G1: Geographic location (country) | H1: Experimental site name | I1: Geographic location (latitude) | J1: Geographic location (longitude) | K1: Geographic location (altitude) | L1: Description of the experimental design | M1: Type of experimental design | N1: Observation unit level hierarchy | O1: Observation unit description | P1: Description of growth facility | Q1: Type of growth facility | R1: Cultural practices | S1: Map of experimental design
A2: studyId | B2: studyTitle | C2: studyDescription | D2: studyStartDate | E2: studyEndDate | F2: contactInst | G2: locationCountry | H2: siteName | I2: locationLatitude | J2: locationLongitude | K2: locationAltitude | L2: expeDesignDesc | M2: expeDesignType | N2: obsUnitLevelHierarchy | O2: obsUnitDesc | P2: growthFacilityDesc | Q2: growthFacilityType | R2: culturalPractice | S2: expeDesignMap
A3: 50 | B3: diversity panel, breeding lines and released cultivars | C3: regular evaluations of plant material for breeding/pre-breeding | D3: 44699 | F3: CZU Prague | G3: India | H3: ICRISAT experimental field | I3: 17.512414 | J3: 78.275371 | L3: Complete randomised block design with 4 replications | O3: microplot (defined in doi:10.1093/jxb/erv251) | P3: LeasyScan (defined in doi:10.1093/jxb/erv251)
A4: 51 | B4: diversity panel, breeding lines and released cultivars | C4: regular evaluations of plant material for breeding/pre-breeding | D4: 44730 | F4: CZU Prague | G4: India | H4: ICRISAT experimental field | I4: 17.512414 | J4: 78.275371 | L4: Complete randomised block design with 4 replications | O4: microplot (defined in doi:10.1093/jxb/erv251) | P4: LeasyScan (defined in doi:10.1093/jxb/erv251)
A5: 59 | B5: diversity panel, breeding lines and released cultivars | C5: regular evaluations of plant material for breeding/pre-breeding | D5: 45130 | F5: CZU Prague | G5: India | H5: ICRISAT experimental field | I5: 17.512414 | J5: 78.275371 | L5: Complete randomised block design with 4 replications | O5: microplot (defined in doi:10.1093/jxb/erv251) | P5: LeasyScan (defined in doi:10.1093/jxb/erv251)

Sheet PERSON
A1: Person name | B1: Person email | C1: Person ID | D1: Person role | E1: Person affiliation
A2: personName | B2: personEmail | C2: personId | D2: personRole | E2: personAffiliation
A3: Jan Masner | B3: masner@pef.czu.cz | D3: Corresponding author | E3: CZU Prague
A4: Others not GDPR compliant

Sheet DATA FILE
A1: Data file link | B1: Data file description | C1: Data file version
A2: dataFileLink | B2: dataFileDesc | C2: dataFileVersion
A3: https://doi.org/10.6084/m9.figshare.28270742 | B3: Annotated 3D point cloud plant scans generated by a high-throughput phenotyping platform (LeasyScan, ICRISAT, India).

Sheet BIOLOGICAL MATERIAL
A1: Biological material ID | B1: Biological material external ID | C1: Organism | D1: Genus | E1: Species | F1: Infraspecific name | G1: Biological material latitude | H1: Biological material longitude | I1: Biological material altitude | J1: Biological material coordinates uncertainty | K1: Biological material preprocessing | L1: Material source ID (Holding institute/stock centre, accession) | M1: Material source DOI | N1: Material source accession number | O1: Material source accession name | P1: Material source institute code | Q1: Material source institute name | R1: Material source other identifiers | S1: Material source latitude | T1: Material source longitude | U1: Material source altitude | V1: Material source coordinates uncertainty | W1: Material source description
A2: biologicalMaterialId | B2: biologicalMaterialExtId | C2: organism | D2: genus | E2: species | F2: infraspecificName | G2: biologicalMaterialLatitude | H2: biologicalMaterialLongitude | I2: biologicalMaterialAltitude | J2: biologicalMaterialCoordUncertainty | K2: biologicalMaterialPreprocessing | L2: materialSourceId | M2: materialSourceDoi | N2: materialSourceAccNumber | O2: materialSourceAccName | P2: materialSourceInstCode | Q2: materialSourceInstName | R2: materialSourceOtherIds | S2: materialSourceLatitude | T2: materialSourceLongitude | U2: materialSourceAltitude | V2: materialSourceCoordUncertainty | W2: materialSourceDesc
A3: mungbean | C3: NCBI:txid157791 | D3: Vigna radiata (mung bean) | E3: Vigna radiata R.Wilczek, 1954 | L3: World Vegetable Centre, Hyderabad
A4: pigeonpea | C4: NCBI:txid3821 | D4: Cajanus cajan (pigeon pea) | E4: Cajanus cajan Huth, 1893 | L4: ICRISAT, Hyderabad
A5: lima bean | C5: NCBI:txid3884 | D5: Phaseolus lunatus (Lima bean) | E5: Phaseolus lunatus L., 1753 | L5: ICRISAT, Hyderabad
A6: cowpea | C6: NCBI:txid3917 | D6: Vigna unguiculata (cowpea) | E6: Vigna unguiculata (L.) Walp., 1843 | L6: ICRISAT, Hyderabad
A7: common bean | C7: NCBI:txid3885 | D7: Phaseolus vulgaris (common bean) | E7: Phaseolus vulgaris L., 1753 | L7: ICRISAT, Hyderabad

Sheet ENVIRONMENT
A1: Environment parameter | B1: Environment parameter value
A2: envParam | B2: envParamValue
A3: Variable planting density | B3: Vertisol

Sheet EXPERIMENTAL FACTOR
A1: Study unique ID | B1: Experimental Factor type | C1: Experimental Factor description | D1: Experimental Factor values
A2: studyId | B2: expeFactorType | C2: expeFactorDesc | D2: expeFactorValues
A3: 50 | B3: fully irrigated trials | C3: irrigation once in 2-3 days till full SWHC | D3: Water
A4: 51 | B4: fully irrigated trials | C4: irrigation once in 2-3 days till full SWHC | D4: Water
A5: 59 | B5: fully irrigated trials | C5: irrigation once in 2-3 days till full SWHC | D5: Water

Sheet EVENT
A1: Study unique ID | B1: Event type | C1: Event accession number | D1: Event description | E1: Event date
A2: studyId | B2: eventType | C2: eventAccNumber | D2: eventDesc | E2: eventDate
A3: 50 | B3: fully fertilized trials | D3: 50kg/ha Di-Amonium-Phosphate, manual application | E3: 44699
A4: 51 | B4: fully fertilized trials | D4: 50kg/ha Di-Amonium-Phosphate, manual application | E4: 44730
A5: 59 | B5: fully fertilized trials | D5: 50kg/ha Di-Amonium-Phosphate, manual application | E5: 45130

Sheet OBSERVATION UNIT
A1: Biological material ID | B1: Study unique ID | C1: Observation unit ID | D1: Observation unit type | E1: Observation unit external ID | F1: Spatial distribution | G1: Observation Unit factor value
A2: biologicalMaterialId | B2: studyId | C2: obsUnitId | D2: obsUnitType | E2: externalId | F2: spatialDistribution | G2: obsUnitFactorValue
A3: mungbean | B3: 50 | C3: 27 0_0 | D3: microplot (defined in doi:10.1093/jxb/erv251) | F3: Latitude:+17.512414; Longitude: +78.2753706 | G3: fully irrigated, fully fertilized, pest- and disease-free
A4: mungbean | B4: 50 | C4: 27 0_1 | D4: microplot (defined in doi:10.1093/jxb/erv251) | F4: Latitude:+17.512414; Longitude: +78.2753707 | G4: fully irrigated, fully fertilized, pest- and disease-free
A5: cowpea | B5: 50 | C5: 27 0_10 | D5: microplot (defined in doi:10.1093/jxb/erv251) | F5: Latitude:+17.512414; Longitude: +78.2753708 | G5: fully irrigated, fully fertilized, pest- and disease-free
A6: cowpea | B6: 50 | C6: 27 0_11 | D6: microplot (defined in doi:10.1093/jxb/erv251) | F6: Latitude:+17.512414; Longitude: +78.2753709 | G6: fully irrigated, fully fertilized, pest- and disease-free
A7: mungbean | B7: 50 | C7: 27 0_2 | D7: microplot (defined in doi:10.1093/jxb/erv251) | F7: Latitude:+17.512414; Longitude: +78.2753710 | G7: fully irrigated, fully fertilized, pest- and disease-free
A8: common bean | B8: 50 | C8: 27 0_3 | D8: microplot (defined in doi:10.1093/jxb/erv251) | F8: Latitude:+17.512414; Longitude: +78.2753711 | G8: fully irrigated, fully fertilized, pest- and disease-free
A9: common bean | B9: 50 | C9: 27 0_4 | D9: microplot (defined in doi:10.1093/jxb/erv251) | F9: Latitude:+17.512414; Longitude: +78.2753712 | G9: fully irrigated, fully fertilized, pest- and disease-free
A10: common bean | B10: 50 | C10: 27 0_5 | D10: microplot (defined in doi:10.1093/jxb/erv251) | F10: Latitude:+17.512414; Longitude: +78.2753713 | G10: fully irrigated, fully fertilized, pest- and disease-free
A11: lima bean | B11: 50 | C11: 27 0_6 | D11: microplot (defined in doi:10.1093/jxb/erv251) | F11: Latitude:+17.512414; Longitude: +78.2753714 | G11: fully irrigated, fully fertilized, pest- and disease-free
A12: lima bean | B12: 50 | C12: 27 0_7 | D12: microplot (defined in doi:10.1093/jxb/erv251) | F12: Latitude:+17.512414; Longitude: +78.2753715 | G12: fully irrigated, fully fertilized, pest- and disease-free
A13: lima bean | B13: 50 | C13: 27 0_8 | D13: microplot (defined in doi:10.1093/jxb/erv251) | F13: Latitude:+17.512414; Longitude: +78.2753716 | G13: fully irrigated, fully fertilized, pest- and disease-free
A14: mungbean | B14: 50 | C14: 27 1_1 | D14: microplot (defined in doi:10.1093/jxb/erv251) | F14: Latitude:+17.512414; Longitude: +78.2753717 | G14: fully irrigated, fully fertilized, pest- and disease-free
... A44: mungbean | B44: 59 | C44: 79 1_8 | D44: microplot (defined in doi:10.1093/jxb/erv251) | F44: Latitude:+17.512414; Longitude: +78.2753747 | G44: fully irrigated, fully fertilized, pest- and disease-free
C46: =_xlfn.CONCAT('Annotated microplots'!C230," ",'Annotated microplots'!D230)

Sheet SAMPLE
A1: Observation unit ID | B1: Sample ID | C1: Plant structure development stage | D1: Plant anatomical entity | E1: Sample description | F1: Collection date | G1: Sample external ID
A2: obsUnitId | B2: sampleId | C2: developmentStage | D2: anatomicalEntity | E2: sampleDesc | F2: collectionDate | G2: externalId
A3: =_xlfn.TEXTBEFORE(_xlfn.TEXTAFTER(B3, "-", 1), "-") & " " & _xlfn.TEXTBEFORE(_xlfn.TEXTAFTER(B3, "-", 2), "-") -> 27 0_0 | B3: ='Annotated microplots'!H3 -> 50-27-0_0-20220524T041419 | C3: whole plant development stage (PO:0007033) | D3: whole plant (PO:0000003) | E3: Plant canopy scan | F3: ='Annotated microplots'!E3 -> 20220524T041419
A4: =_xlfn.TEXTBEFORE(_xlfn.TEXTAFTER(B4, "-", 1), "-") & " " & _xlfn.TEXTBEFORE(_xlfn.TEXTAFTER(B4, "-", 2), "-") -> 27 0_0 | B4: ='Annotated microplots'!H4 -> 50-27-0_0-20220525T030449 | C4: whole plant development stage (PO:0007033) | D4: whole plant (PO:0000003) | E4: Plant canopy scan | F4: ='Annotated microplots'!E4 -> 20220525T030449
A5: =_xlfn.TEXTBEFORE(_xlfn.TEXTAFTER(B5, "-", 1), "-") & " " & _xlfn.TEXTBEFORE(_xlfn.TEXTAFTER(B5, "-", 2), "-") -> 27 0_0 | B5: ='Annotated microplots'!H5 -> 50-27-0_0-20220527T045102 | C5: whole plant development stage (PO:0007033) | D5: whole plant (PO:0000003) | E5: Plant canopy scan | F5: ='Annotated microplots'!E5 -> 20220527T045102
A6: =_xlfn.TEXTBEFORE(_xlfn.TEXTAFTER(B6, "-", 1), "-") & " " & _xlfn.TEXTBEFORE(_xlfn.TEXTAFTER(B6, "-", 2), "-") -> 27 0_0 | B6: ='Annotated microplots'!H6 -> 50-27-0_0-20220530T074538 | C6: whole plant development stage (PO:0007033) | D6: whole plant (PO:0000003) | E6: Plant canopy scan | F6: ='Annotated microplots'!E6 -> 20220530T074538
A7: =_xlfn.TEXTBEFORE(_xlfn.TEXTAFTER(B7, "-", 1), "-") & " " & _xlfn.TEXTBEFORE(_xlfn.TEXTAFTER(B7, "-", 2), "-") -> 27 0_0 | B7: ='Annotated microplots'!H7 -> 50-27-0_0-20220531T042054 | C7: whole plant development stage (PO:0007033) | D7: whole plant (PO:0000003) | E7: Plant canopy scan | F7: ='Annotated microplots'!E7 -> 20220531T042054
A8: =_xlfn.TEXTBEFORE(_xlfn.TEXTAFTER(B8, "-", 1), "-") & " " & _xlfn.TEXTBEFORE(_xlfn.TEXTAFTER(B8, "-", 2), "-") -> 27 0_0 | B8: ='Annotated microplots'!H8 -> 50-27-0_0-20220601T033109 | C8: whole plant development stage (PO:0007033) | D8: whole plant (PO:0000003) | E8: Plant canopy scan | F8: ='Annotated microplots'!E8 -> 20220601T033109
A9: =_xlfn.TEXTBEFORE(_xlfn.TEXTAFTER(B9, "-", 1), "-") & " " & _xlfn.TEXTBEFORE(_xlfn.TEXTAFTER(B9, "-", 2), "-") -> 27 0_0 | B9: ='Annotated microplots'!H9 -> 50-27-0_0-20220602T052138 | C9: whole plant development stage (PO:0007033) | D9: whole plant (PO:0000003) | E9: Plant canopy scan | F9: ='Annotated microplots'!E9 -> 20220602T052138
A10: =_xlfn.TEXTBEFORE(_xlfn.TEXTAFTER(B10, "-", 1), "-") & " " & _xlfn.TEXTBEFORE(_xlfn.TEXTAFTER(B10, "-", 2), "-") -> 27 0_1 | B10: ='Annotated microplots'!H10 -> 50-27-0_1-20220523T042520 | C10: whole plant development stage (PO:0007033) | D10: whole plant (PO:0000003) | E10: Plant canopy scan | F10: ='Annotated microplots'!E10 -> 20220523T042520
A11: =_xlfn.TEXTBEFORE(_xlfn.TEXTAFTER(B11, "-", 1), "-") & " " & _xlfn.TEXTBEFORE(_xlfn.TEXTAFTER(B11, "-", 2), "-") -> 27 0_1 | B11: ='Annotated microplots'!H11 -> 50-27-0_1-20220524T041419 | C11: whole plant development stage (PO:0007033) | D11: whole plant (PO:0000003) | E11: Plant canopy scan | F11: ='Annotated microplots'!E11 -> 20220524T041419
A12: =_xlfn.TEXTBEFORE(_xlfn.TEXTAFTER(B12, "-", 1), "-") & " " & _xlfn.TEXTBEFORE(_xlfn.TEXTAFTER(B12, "-", 2), "-") -> 27 0_1 | B12: ='Annotated microplots'!H12 -> 50-27-0_1-20220525T030449 | C12: whole plant development stage (PO:0007033) | D12: whole plant (PO:0000003) | E12: Plant canopy scan | F12: ='Annotated microplots'!E12 -> 20220525T030449
A13: =_xlfn.TEXTBEFORE(_xlfn.TEXTAFTER(B13, "-", 1), "-") & " " & _xlfn.TEXTBEFORE(_xlfn.TEXTAFTER(B13, "-", 2), "-") -> 27 0_1 | B13: ='Annotated microplots'!H13 -> 50-27-0_1-20220527T045102 | C13: whole plant development stage (PO:0007033) | D13: whole plant (PO:0000003) | E13: Plant canopy scan | F13: ='Annotated microplots'!E13 -> 20220527T045102
A14: =_xlfn.TEXTBEFORE(_xlfn.TEXTAFTER(B14, "-", 1), "-") & " " & _xlfn.TEXTBEFORE(_xlfn.TEXTAFTER(B14, "-", 2), "-") -> 27 0_1 | B14: ='Annotated microplots'!H14 -> 50-27-0_1-20220530T074538 | C14: whole plant development stage (PO:0007033) | D14: whole plant (PO:0000003) | E14: Plant canopy scan | F14: ='Annotated microplots'!E14 -> 20220530T074538
... A229: =_xlfn.TEXTBEFORE(_xlfn.TEXTAFTER(B229, "-", 1), "-") & " " & _xlfn.TEXTBEFORE(_xlfn.TEXTAFTER(B229, "-", 2), "-") -> 79 1_8 | B229: ='Annotated microplots'!H229 -> 59-79-1_8-20230729T054442 | C229: whole plant development stage (PO:0007033) | D229: whole plant (PO:0000003) | E229: Plant canopy scan | F229: ='Annotated microplots'!E229 -> 20230729T054442
